 * Running on http://0.0.0.0:5000/ (Press CTRL+C to quit)
192.168.4.4 - - [06/Jun/2018 17:08:26] "GET / HTTP/1.1" 200 -
192.168.4.4 - - [06/Jun/2018 17:08:26] "GET /video_feed HTTP/1.1" 500 -
Error on request:
Traceback (most recent call last):
  File "/home/pi/.virtualenvs/cv/lib/python3.5/site-packages/werkzeug/serving.py", line 270, in run_wsgi
    execute(self.server.app)
  File "/home/pi/.virtualenvs/cv/lib/python3.5/site-packages/werkzeug/serving.py", line 260, in execute
    for data in application_iter:
  File "/home/pi/.virtualenvs/cv/lib/python3.5/site-packages/werkzeug/wsgi.py", line 870, in __next__
    return self._next()
  File "/home/pi/.virtualenvs/cv/lib/python3.5/site-packages/werkzeug/wrappers.py", line 82, in _iter_encoded
    for item in iterable:
  File "/home/pi/CV-stream/app.py", line 126, in gen
    while True and eyeless == false:
NameError: name 'false' is not defined
192.168.4.4 - - [06/Jun/2018 17:08:28] "GET / HTTP/1.1" 200 -
192.168.4.4 - - [06/Jun/2018 17:08:28] "GET /video_feed HTTP/1.1" 500 -
Error on request:
Traceback (most recent call last):
  File "/home/pi/.virtualenvs/cv/lib/python3.5/site-packages/werkzeug/serving.py", line 270, in run_wsgi
    execute(self.server.app)
  File "/home/pi/.virtualenvs/cv/lib/python3.5/site-packages/werkzeug/serving.py", line 260, in execute
    for data in application_iter:
  File "/home/pi/.virtualenvs/cv/lib/python3.5/site-packages/werkzeug/wsgi.py", line 870, in __next__
    return self._next()
  File "/home/pi/.virtualenvs/cv/lib/python3.5/site-packages/werkzeug/wrappers.py", line 82, in _iter_encoded
    for item in iterable:
  File "/home/pi/CV-stream/app.py", line 126, in gen
    while True and eyeless == false:
NameError: name 'false' is not defined
192.168.4.4 - - [06/Jun/2018 17:08:32] "GET / HTTP/1.1" 200 -
192.168.4.4 - - [06/Jun/2018 17:08:32] "GET /video_feed HTTP/1.1" 500 -
Error on request:
Traceback (most recent call last):
  File "/home/pi/.virtualenvs/cv/lib/python3.5/site-packages/werkzeug/serving.py", line 270, in run_wsgi
    execute(self.server.app)
  File "/home/pi/.virtualenvs/cv/lib/python3.5/site-packages/werkzeug/serving.py", line 260, in execute
    for data in application_iter:
  File "/home/pi/.virtualenvs/cv/lib/python3.5/site-packages/werkzeug/wsgi.py", line 870, in __next__
    return self._next()
  File "/home/pi/.virtualenvs/cv/lib/python3.5/site-packages/werkzeug/wrappers.py", line 82, in _iter_encoded
    for item in iterable:
  File "/home/pi/CV-stream/app.py", line 126, in gen
    while True and eyeless == false:
NameError: name 'false' is not defined
192.168.4.4 - - [06/Jun/2018 17:08:37] "GET /video_feed HTTP/1.1" 500 -
Error on request:
Traceback (most recent call last):
  File "/home/pi/.virtualenvs/cv/lib/python3.5/site-packages/werkzeug/serving.py", line 270, in run_wsgi
    execute(self.server.app)
  File "/home/pi/.virtualenvs/cv/lib/python3.5/site-packages/werkzeug/serving.py", line 260, in execute
    for data in application_iter:
  File "/home/pi/.virtualenvs/cv/lib/python3.5/site-packages/werkzeug/wsgi.py", line 870, in __next__
    return self._next()
  File "/home/pi/.virtualenvs/cv/lib/python3.5/site-packages/werkzeug/wrappers.py", line 82, in _iter_encoded
    for item in iterable:
  File "/home/pi/CV-stream/app.py", line 126, in gen
    while True and eyeless == false:
NameError: name 'false' is not defined
/home/pi/CV-stream/on_reboot.sh: line 6:  1031 Terminated              python3 app.py
 * Running on http://0.0.0.0:5000/ (Press CTRL+C to quit)
192.168.4.4 - - [06/Jun/2018 17:14:27] "GET /video_feed HTTP/1.1" 200 -
192.168.4.4 - - [06/Jun/2018 17:15:11] "GET / HTTP/1.1" 200 -
192.168.4.4 - - [06/Jun/2018 17:15:11] "GET /video_feed HTTP/1.1" 200 -
